Workbook

Sheet AI-SP-26
CR1: Assessment of GA's | HP1: Attainment of GAs | HQ1: Attainment of Graduate Attribute
B2: Student Name | C2: Semester 1 | AA2: Semester 2 | AZ2: Semester 3 | BW2: Semester 4 | CR2: Semester 5 | EA2: Semester 6 | FD2: Semester 7 | GJ2: Semester - 8
C3: Application of information & Communication Technologies | H3: Applied Physics | L3: Programming Fundamentals | Q3: Calculus and Analytic Geometry | U3: Functional English | AA3: Expository Writing | AC3: Object Oriented Programming | AI3: Discreate Structures | AL3: Ideology and Constitution of Pakistan | AQ3: Digital Logic Design | AV3: Multi Variable Calculus | AZ3: Data Structures | BC3: Computer Organization & Assembly Language | BF3: Introduction to Artificial Intelligence | BI3: Computer Network | BP3: Probability & Statistics | BW3: Design Analysis of Algorithms | CC3: Data Structures and Algorithms | CG3: Applied Statistics | CL3: Software Engineering | CO3: World History | CR3: Artificial Intelligence | CW3: Data Communication & Computer Networks | DB3: Continuous Discreate Optimization | DG3: Data Base Management Systems | DM3: Introduction to Python Lab | DT3: World Literature | EA3: Machine Learning | EF3: Computer Vision | EL3: Parallel and Distributed Computing | ER3: Academic & Professional Writing | EU3: Logical And Automated Reasoning | EX3: Data Visualization | FD3: Artificial Intelligence | FI3: Philosophy and Critical Thinking | FK3: Natural Language Processing | FP3: Final Year Project - I | GB3: Logical And Automated Reasoning | GF3: Philosophy and Critical Thinking | GJ3: Deep Learning | GO3: Artificial Intelligence for Robotics | GT3: Sociology | GW3: Ethics and Social Responsibility | GZ3: Philosophy and Critical Thinking | HD3: Final Year Project - II
C4: CLO 1 | D4: CLO 2 | E4: CLO 3 | F4: CLO 1 | G4: CLO 2 | H4: CLO 1 | I4: CLO 2 | J4: CLO 3 | K4: CLO 1 | L4: CLO 1 | M4: CLO 2 | N4: CLO 3 | O4: CLO1 | P4: CLO2 | Q4: CLO 1 | R4: CLO 2 | S4: CLO 3 | T4: CLO 3 | U4: CLO 1 | V4: CLO 2 | W4: CLO 3 | X4: CLO 4 | AA4: CLO 1 | AB4: CLO 2 | AC4: CLO 1 | AD4: CLO 2 | AE4: CLO 3 | AF4: CLO 4 | AG4: CLO 1 | AH4: CLO 2 | AI4: CLO 1 | AJ4: CLO 2 | AK4: CLO 3 | AL4: CLO 1 | AM4: CLO 2 | AN4: CLO 3 | AO4: CLO4 | AP4: CLO5 | AQ4: CLO 1 | AR4: CLO 2 | AS4: CLO 3 | AT4: CLO 5 | AU4: CLO 4 | AV4: CLO 1 | AW4: CLO 2 | AX4: CLO 3 | AY4: CLO 4 | AZ4: CLO 1 | BA4: CLO 2 | BB4: CLO 3 | BC4: CLO 1 | BD4: CLO 2 | BE4: CLO 3 | BF4: CLO 1 | BG4: CLO 2 | BH4: CLO 3 | BI4: CLO 1 | BJ4: CLO 2 | BK4: CLO 3 | BL4: CLO 4 | BM4: CLO 5 | BN4: CLO 6 | BO4: CLO 7 | BP4: CLO 1 | BQ4: CLO 2 | BR4: CLO 3 | BS4: CLO 4 | BT4: CLO 5 | BU4: CLO 1 | BV4: CLO 2 | BW4: CLO 1 | BX4: CLO 2 | BY4: CLO 3 | BZ4: CLO 4 | CA4: CLO 5 | CB4: CLO 6 | CC4: CLO 1 | CD4: CLO 2 | CE4: CLO 3 | CF4: CLO 4 | CG4: CLO 1 | CH4: CLO 2 | CI4: CLO 3 | CJ4: CLO 1 | CK4: CLO 2 | CL4: CLO 1 | CM4: CLO 2 | CN4: CLO 3 | CO4: CLO 1 | CP4: CLO 2 | CQ4: CLO 3 | CR4: CLO1 | CS4: CLO2 | CT4: CLO 3 | CU4: CLO 1 | CV4: CLO 2 | CW4: CLO 1 | CX4: CLO 2 | CY4: CLO 3 | CZ4: CLO 1 | DA4: CLO 2 | DB4: CLO1 | DC4: CLO2 | DD4: CLO3 | DE4: CLO1 | DF4: CLO2 | DG4: CLO1 | DH4: CLO2 | DI4: CLO3 | DJ4: CLO4 | DK4: CLO1 | DL4: CLO2 | DM4: CLO1 | DN4: CLO2 | DO4: CLO3 | DP4: CLO4 | DQ4: CLO5 | DR4: CLO6 | DS4: CLO7 | DT4: CLO1 | DU4: CLO2 | DV4: CLO3 | DW4: CLO4 | DX4: CLO5 | DY4: CLO6 | DZ4: CLO7 | EA4: CLO1 | EB4: CLO2 | EC4: CLO3 | ED4: CLO1 | EE4: CLO2 | EF4: CLO1 | EG4: CLO2 | EH4: CLO3 | EI4: CLO4 | EJ4: CLO5 | EK4: CLO6 | EL4: CLO1 | EM4: CLO 2 | EN4: CLO 3 | EO4: CLO 4 | EQ4: CLO3 | ER4: CLO1 | ES4: CLO2 | ET4: CLO7 | EU4: CLO1 | EV4: CLO2 | EW4: CLO3 | EX4: CLO1 | EY4: CLO2 | EZ4: CLO3 | FA4: CLO4 | FB4: CLO 1 | FC4: CLO 2 | FD4: CLO1 | FE4: CLO2 | FF4: CLO 3 | FG4: CLO 1 | FH4: CLO 2 | FI4: CLO1 | FJ4: CLO2 | FK4: CLO1 | FL4: CLO2 | FM4: CLO3 | FN4: CLO 1 | FO4: CLO 2 | FP4: R1 | FQ4: R2 | FR4: R3 | FS4: R4 | FT4: R5 | FU4: R6 | FV4: R7 | FW4: R8 | FX4: R9 | FY4: R10 | FZ4: R11 | GA4: R12 | GB4: CLO 1 | GC4: CLO 2 | GD4: CLO 3 | GE4: CLO 4 | GJ4: CLO1 | GK4: CLO 2 | GL4: CLO 3 | GM4: CLO 1 | GN4: CLO 2 | GO4: CLO1 | GP4: CLO2 | GQ4: CLO3 | GR4: CLO 1 | GS4: CLO 2 | GT4: CLO1 | GU4: CLO2 | GV4: CLO3 | GW4: CLO1 | GX4: CLO2 | GY4: CLO3 | HD4: R1 | HE4: R2 | HF4: R3 | HG4: R4 | HH4: R5 | HI4: R6 | HJ4: R7 | HK4: R8 | HL4: R9 | HM4: R10 | HN4: R11 | HO4: R12 | HQ4: GA1 | HR4: GA2 | HS4: GA3 | HT4: GA4 | HU4: GA5 | HV4: GA6 | HW4: GA7 | HX4: GA8 | HY4: GA9 | HZ4: GA10
C5: Theory | F5: Lab | H5: Theory | K5: Lab | L5: Theory | O5: Lab | Q5: Theory | U5: Theory | AG5: Lab | BQ5: Theory | BU5: Lab | CE5: Lab | CG5: Theory | CJ5: Lab | CL5: GA 2 | CM5: GA 3 | CN5: GA 5 | CR5: Theory | CU5: Lab | CW5: Theory | CZ5: Lab | DB5: Theory | DE5: Lab | DG5: Theory | DK5: Lab | EA5: Theory | ED5: Lab | EL5: Theory | EP5: Lab | EU5: Theory | EX5: Theory | FB5: Lab | FD5: Theory | FG5: Lab | FK5: Theory | FN5: Lab | GJ5: Theory | GM5: Lab | GO5: Theory | GR5: Lab
C6: GA1 | D6: GA 2 | E6: GA4 | F6: GA1 | G6: GA 2 | H6: GA2 | I6: GA 2 | J6: GA2 | K6: GA5 | L6: GA 1 | M6: GA 2 | N6: GA 4 | O6: GA 2 | P6: GA 5 | Q6: GA 1 | R6: GA 2 | S6: GA 3 | T6: GA 4 | U6: GA 5 | V6: GA 5 | W6: GA 7 | X6: GA 2 | AA6: GA10 | AC6: GA 2 | AE6: GA 4 | AG6: GA 4 | AH6: GA 5 | AI6: GA1 | AL6: GA1 | AM6: GA 2 | AQ6: GA1 | AU6: GA4 | AV6: GA1 | AW6: GA2 | AX6: GA1 | AY6: GA2 | AZ6: GA5 | BB6: GA1 | BC6: GA2 | BE6: GA4 | BF6: GA6 | BG6: GA7 | BH6: GA8 | BI6: GA1 | BN6: GA8 | BO6: GA10 | BP6: GA1 | BQ6: GA2 | BS6: GA 5 | BU6: GA 2 | BV6: GA5 | BW6: GA2 | BX6: GA3 | BY6: GA2 | BZ6: GA4 | CA6: GA8 | CB6: GA10 | CC6: GA 2 | CD6: GA 5 | CE6: GA 2 | CF6: GA 3 | CG6: GA2 | CH6: GA3 | CI6: GA5 | CJ6: GA8 | CK6: GA10 | CL6: PLO10 | CM6: PLO9 | CN6: PLO5 | CO6: PLO1 | CQ6: PLO3 | CR6: GA 1 | CS6: GA 2 | CT6: GA 3 | CU6: GA 4 | CV6: GA 5 | CW6: GA2 | CX6: GA3 | CY6: GA5 | CZ6: GA8 | DA6: GA10 | DB6: GA 1 | DC6: GA 2 | DD6: GA 5 | DE6: GA 5 | DG6: GA 1 | DH6: GA 3 | DI6: GA 4 | DJ6: GA 5 | DK6: GA 4 | DM6: PLO2 | DP6: PLO3 | DQ6: PLO5 | DR6: PLO8 | DS6: PLO10 | DT6: PLO2 | DV6: PLO3 | DW6: PLO5 | DX6: PLO1 | DY6: PLO8 | DZ6: PLO10 | EA6: GA 1 | EB6: GA 3 | ED6: GA 1 | EE6: GA 3 | EF6: PLO1 | EG6: PLO3 | EH6: PLO2 | EI6: PLO5 | EJ6: PLO8 | EK6: PLO10 | EL6: GA 1 | EM6: GA 2 | EN6: GA 3 | EO6: GA 4 | ER6: GA 1 | ES6: GA 7 | ET6: GA 8 | EU6: GA 1 | EV6: GA 2 | EW6: GA 9 | EX6: GA2 | EY6: GA 2 | EZ6: GA 3 | FA6: GA 5 | FB6: GA 3 | FC6: GA 4 | FD6: GA 1 | FE6: GA 2 | FF6: GA 3 | FG6: GA 4 | FH6: GA 5 | FI6: PLO4 | FJ6: PLO5 | FK6: GA 1 | FL6: GA 2 | FM6: GA 3 | FN6: GA 1 | FO6: GA 3 | FP6: GA1 | FQ6: GA2 | FR6: GA3 | FS6: GA4 | FT6: GA5 | FU6: GA6 | FV6: GA7 | FW6: GA8 | FX6: GA9 | FY6: GA10 | FZ6: GA11 | GA6: GA12 | GJ6: GA 1 | GK6: GA 3 | GM6: GA 1 | GN6: GA 3 | GO6: GA 1 | GP6: GA 2 | GQ6: GA 5 | GR6: GA 5 | GT6: PLO1 | GW6: PLO1 | GX6: PLO2 | GY6: PLO5 | HD6: GA1 | HE6: GA2 | HF6: GA3 | HG6: GA4 | HH6: GA5 | HI6: GA6 | HJ6: GA7 | HK6: GA8 | HL6: GA9 | HM6: GA10 | HN6: GA11 | HO6: GA12
A7: 052-26-128002 | B7: Muhammad Umar Jalal | C7: 59.05 | D7: 78.89 | E7: 85.65 | F7: 59.05 | G7: 78.89 | H7: 75.43 | I7: 66 | J7: 66 | K7: 94.21 | HQ7: =AVERAGE(F7,K7,L7) | HR7: =AVERAGE(C7,#REF!,M7,O7,Q7,U7,Z7) | HS7: =AVERAGE(R7) | HT7: =AVERAGE(N7) | HU7: =AVERAGE(V7,P7,#REF!) | HW7: =AVERAGE(X7) | HZ7: =AVERAGE(Y7)
A8: 052-26-128003 | B8: Iftikhar Ahmed | C8: 53.57 | D8: 48.33 | E8: 85.65 | F8: 53.57 | G8: 48.33 | H8: 53.71 | I8: 83.5 | J8: 83.5 | K8: 75.61 | HQ8: =AVERAGE(F8,K8,L8) | HR8: =AVERAGE(C8,#REF!,M8,O8,Q8,U8,Z8) | HS8: =AVERAGE(R8) | HT8: =AVERAGE(N8) | HU8: =AVERAGE(V8,P8,#REF!) | HW8: =AVERAGE(X8) | HZ8: =AVERAGE(Y8)
A9: 052-26-128005 | B9: Shah nawaz | C9: 83.81 | D9: 61.39 | E9: 90 | F9: 83.81 | G9: 61.39 | H9: 7 | I9: 62 | J9: 20.5 | K9: 92.28 | HQ9: =AVERAGE(F9,K9,L9) | HR9: =AVERAGE(C9,#REF!,M9,O9,Q9,U9,Z9) | HS9: =AVERAGE(R9) | HT9: =AVERAGE(N9) | HU9: =AVERAGE(V9,P9,#REF!) | HW9: =AVERAGE(X9) | HZ9: =AVERAGE(Y9)
A10: 052-26-128006 | B10: Hamid Safeer | C10: 77.38 | D10: 70.28 | E10: 85.65 | F10: 77.38 | G10: 70.28 | H10: 69 | I10: 81.67 | J10: 79.23 | K10: 81.93 | HQ10: =AVERAGE(F10,K10,L10) | HR10: =AVERAGE(C10,#REF!,M10,O10,Q10,U10,Z10) | HS10: =AVERAGE(R10) | HT10: =AVERAGE(N10) | HU10: =AVERAGE(V10,P10,#REF!) | HW10: =AVERAGE(X10) | HZ10: =AVERAGE(Y10)
A11: 052-26-128008 | B11: Aazib Ilyas | C11: 83.33 | D11: 73.06 | E11: 85.65 | F11: 83.33 | G11: 73.06 | H11: 42 | I11: 48.67 | J11: 48.67 | K11: 85.96 | HQ11: =AVERAGE(F11,K11,L11) | HR11: =AVERAGE(C11,#REF!,M11,O11,Q11,U11,Z11) | HS11: =AVERAGE(R11) | HT11: =AVERAGE(N11) | HU11: =AVERAGE(V11,P11,#REF!) | HW11: =AVERAGE(X11) | HZ11: =AVERAGE(Y11)
A12: 052-26-128012 | B12: Alishba Rasheed | C12: 75.71 | D12: 69.44 | E12: 90 | F12: 75.71 | G12: 69.44 | H12: 53.43 | I12: 68 | J12: 68 | K12: 84.04 | HQ12: =AVERAGE(F12,K12,L12) | HR12: =AVERAGE(C12,#REF!,M12,O12,Q12,U12,Z12) | HS12: =AVERAGE(R12) | HT12: =AVERAGE(N12) | HU12: =AVERAGE(V12,P12,#REF!) | HW12: =AVERAGE(X12) | HZ12: =AVERAGE(Y12)
A13: 052-26-128013 | B13: ABDUR REHMAN | C13: 82.14 | D13: 66.94 | E13: 85.65 | F13: 82.14 | G13: 66.94 | H13: 50 | I13: 57.67 | J13: 50.23 | K13: 82.28 | HQ13: =AVERAGE(F13,K13,L13) | HR13: =AVERAGE(C13,#REF!,M13,O13,Q13,U13,Z13) | HS13: =AVERAGE(R13) | HT13: =AVERAGE(N13) | HU13: =AVERAGE(V13,P13,#REF!) | HW13: =AVERAGE(X13) | HZ13: =AVERAGE(Y13)
A14: 052-26-128016 | B14: Muzammil Ashraf | C14: 50 | D14: 54.44 | E14: 85.65 | F14: 50 | G14: 54.44 | H14: 82.29 | I14: 90 | J14: 90 | K14: 99.12 | HQ14: =AVERAGE(F14,K14,L14) | HR14: =AVERAGE(C14,#REF!,M14,O14,Q14,U14,Z14) | HS14: =AVERAGE(R14) | HT14: =AVERAGE(N14) | HU14: =AVERAGE(V14,P14,#REF!) | HW14: =AVERAGE(X14) | HZ14: =AVERAGE(Y14)
A15: 052-26-128017 | B15: TOUFEEQ UMAR | C15: 73.81 | D15: 66.94 | E15: 88.55 | F15: 73.81 | G15: 66.94 | H15: 56.43 | I15: 65.67 | J15: 65.67 | K15: 94.91 | HQ15: =AVERAGE(F15,K15,L15) | HR15: =AVERAGE(C15,#REF!,M15,O15,Q15,U15,Z15) | HS15: =AVERAGE(R15) | HT15: =AVERAGE(N15) | HU15: =AVERAGE(V15,P15,#REF!) | HW15: =AVERAGE(X15) | HZ15: =AVERAGE(Y15)
A16: 052-26-128020 | B16: Adil Kamal | C16: 61.9 | D16: 70.83 | E16: 78.41 | F16: 61.9 | G16: 70.83 | H16: 84.29 | I16: 85 | J16: 85 | K16: 87.37 | HQ16: =AVERAGE(F16,K16,L16) | HR16: =AVERAGE(C16,#REF!,M16,O16,Q16,U16,Z16) | HS16: =AVERAGE(R16) | HT16: =AVERAGE(N16) | HU16: =AVERAGE(V16,P16,#REF!) | HW16: =AVERAGE(X16) | HZ16: =AVERAGE(Y16)
A17: 052-26-128023 | B17: IBADUR RAHMAN | C17: 64.29 | D17: 68.61 | E17: 85.65 | F17: 64.29 | G17: 68.61 | H17: 50.43 | I17: 50.67 | J17: 50.62 | K17: 90.18 | HQ17: =AVERAGE(F17,K17,L17) | HR17: =AVERAGE(C17,#REF!,M17,O17,Q17,U17,Z17) | HS17: =AVERAGE(R17) | HT17: =AVERAGE(N17) | HU17: =AVERAGE(V17,P17,#REF!) | HW17: =AVERAGE(X17) | HZ17: =AVERAGE(Y17)
A18: 052-26-128026 | B18: Rao Saim Naeem | C18: 100 | D18: 74.44 | E18: 85.65 | F18: 100 | G18: 74.44 | H18: 32 | I18: 63 | J18: 22.87 | K18: 90.7 | HQ18: =AVERAGE(F18,K18,L18) | HR18: =AVERAGE(C18,#REF!,M18,O18,Q18,U18,Z18) | HS18: =AVERAGE(R18) | HT18: =AVERAGE(N18) | HU18: =AVERAGE(V18,P18,#REF!) | HW18: =AVERAGE(X18) | HZ18: =AVERAGE(Y18)
... A26: 052-26-128071 | B26: Muhammad subhan sikander | C26: 78.33 | D26: 71.11 | E26: 87.1 | F26: 78.33 | G26: 71.11 | H26: 50.71 | I26: 53.98 | J26: 56.56 | K26: 83.68 | HQ26: =AVERAGE(F26,K26,L26) | HR26: =AVERAGE(C26,#REF!,M26,O26,Q26,U26,Z26) | HS26: =AVERAGE(R26) | HT26: =AVERAGE(N26) | HU26: =AVERAGE(V26,P26,#REF!) | HW26: =AVERAGE(X26) | HZ26: =AVERAGE(Y26)
A27: 052-26-128083 | B27: awais mehmood | C27: 70 | D27: 54.44 | E27: 85.65 | F27: 70 | G27: 54.44 | H27: 88 | I27: 92 | J27: 92 | K27: 78.6 | Y27: =AVERAGE(Y7:Y25) | Z27: =AVERAGE(Z7:Z25) | AA27: =AVERAGE(AA7:AA25) | AB27: =AVERAGE(AB7:AB25) | AC27: =AVERAGE(AC7:AC25) | AD27: =AVERAGE(AD7:AD25) | AE27: =AVERAGE(AE7:AE25) | AF27: =AVERAGE(AF7:AF25) | ... AM27: =AVERAGE(AM7:AM25) | AQ27: =AVERAGE(AQ7:AQ25) | AR27: =AVERAGE(AR7:AR25) | AS27: =AVERAGE(AS7:AS25) | AT27: =AVERAGE(AT7:AT25) | AU27: =AVERAGE(AU7:AU25) | AV27: =AVERAGE(AV7:AV25) | AW27: =AVERAGE(AW7:AW25) | AX27: =AVERAGE(AX7:AX25) | ... EP27: =AVERAGE(EP7:EP25) | ER27: =AVERAGE(ER7:ER25) | ES27: =AVERAGE(ES7:ES25) | ET27: =AVERAGE(ET7:ET25) | EU27: =AVERAGE(EU7:EU25) | EV27: =AVERAGE(EV7:EV25) | EW27: =AVERAGE(EW7:EW25) | EX27: =AVERAGE(EX7:EX25) | EZ27: =AVERAGE(EZ7:EZ25) | FA27: =AVERAGE(FA7:FA25) | FB27: =AVERAGE(FB7:FB25) | FC27: =AVERAGE(FC7:FC25) | FD27: =AVERAGE(FD7:FD25) | FE27: =AVERAGE(FE7:FE25) | FF27: =AVERAGE(FF7:FF25) | FG27: =AVERAGE(FG7:FG25) | ... HO27: =AVERAGE(HO7:HO25) | HQ27: =AVERAGE(HQ7:HQ26) | HR27: =AVERAGE(HR7:HR26) | HS27: =AVERAGE(HS7:HS26) | HT27: =AVERAGE(HT7:HT26) | HU27: =AVERAGE(HU7:HU26) | HW27: =AVERAGE(HW7:HW26) | HZ27: =AVERAGE(HZ7:HZ26)
A28: 052-26-128084 | B28: Muhammad Hassan | C28: 50 | D28: 54.44 | E28: 56.67 | F28: 50 | G28: 54 | H28: 0 | I28: 0 | J28: 0 | K28: 78.25
A29: 052-26-128085 | B29: Nimra bibi | C29: 64.29 | D29: 67.78 | E29: 85.65 | F29: 64.29 | G29: 67.78 | H29: 46 | I29: 66 | J29: 66 | K29: 88.6
A30: 052-26-128087 | B30: Saqib Ahmad | C30: 82.14 | D30: 66.94 | E30: 85.65 | F30: 82.14 | G30: 66.94 | H30: 54 | I30: 55.33 | J30: 55.33 | K30: 93.86
A31: 052-26-128096 | B31: Sahar Saleem | C31: 33.33 | D31: 54.44 | E31: 56.67 | F31: 33.33 | G31: 54.44 | H31: 0 | I31: 0 | J31: 0 | K31: 75.96
A32: 052-26-128097 | B32: Abdullah zulfqar | C32: 72.62 | D32: 66.67 | E32: 85.65 | F32: 72.62 | G32: 66.67 | H32: 51.09 | I32: 77 | J32: 50.23 | K32: 74.56
A33: 052-26-128102 | B33: Abdul Rahman | C33: 69.05 | D33: 68.33 | E33: 85.65 | F33: 69.05 | G33: 68.33 | H33: 80.43 | I33: 71.33 | J33: 71.33 | K33: 79.3
A34: 052-26-128105 | B34: Shariq | C34: 64.29 | D34: 68.06 | E34: 85.65 | F34: 64.29 | G34: 68.06 | H34: 24 | I34: 17 | J34: 11.98 | K34: 89.65
A35: 052-26-128122 | B35: Muhammad Saad Ali Sajjad | C35: 80.95 | D35: 71.11 | E35: 85.65 | F35: 80.95 | G35: 71.11 | H35: 41.43 | I35: 30 | J35: 25.98 | K35: 90.7
A36: 052-26-128147 | B36: Jawad Ahmed | C36: 60.95 | D36: 67.78 | E36: 85.65 | F36: 60.95 | G36: 67.78 | H36: 20 | I36: 40 | J36: 17.67 | K36: 85.09
A37: 052-26-128154 | B37: Abdullah khalil | C37: 73.81 | D37: 68.06 | E37: 85.65 | F37: 73.81 | G37: 68.06 | H37: 86.29 | I37: 90.67 | J37: 90.67 | K37: 81.93
A38: 052-26-128156 | B38: Syed Haseeb Ali Haider | C38: 85.71 | D38: 68.89 | E38: 85.65 | F38: 85.71 | G38: 68.89 | H38: 52.43 | I38: 52.98 | J38: 56.78 | K38: 72.98
A39: 052-26-128160 | B39: Anas Raza Khan | C39: 91.67 | D39: 73.06 | E39: 85.65 | F39: 91.67 | G39: 73.06 | H39: 69.14 | I39: 83.33 | J39: 56.78 | K39: 78.6
... A59: 052-26-128267 | B59: Umm-e- Farwa | C59: 84 | D59: 78.89 | E59: 85.65 | F59: 73.81 | G59: 68.06 | H59: 79.43 | I59: 86.67 | J59: 86.67 | K59: 0
C60: =AVERAGE(C7:C59) | D60: =AVERAGE(D7:D59) | E60: =AVERAGE(E7:E59) | F60: =AVERAGE(F7:F59) | G60: =AVERAGE(G7:G59) | H60: =AVERAGE(H7:H59) | I60: =AVERAGE(I7:I59) | J60: =AVERAGE(J7:J59) | ... HO60: =AVERAGE(HO7:HO59)

Sheet AI-FA-25
A1: Batch Spring 2025 | CV1: Assessment of GA's | HT1: Attainment of GAs | HU1: Attainment of Graduate Attribute
B2: Sr. No. | D2: Student Name | E2: Semester 1 | AE2: Semester 2 | BD2: Semester 3 | CA2: Semester 4 | CV2: Semester 5 | EE2: Semester 6 | FH2: Semester 7 | GN2: Semester - 8
E3: Application of information & Communication Technologies | K3: Applied Physics | P3: Programming Fundamentals | U3: Calculus and Analytic Geometry | Y3: Functional English | AE3: Expository Writing | AG3: Object Oriented Programming | AM3: Discreate Structures | AP3: Ideology and Constitution of Pakistan | AU3: Digital Logic Design | AZ3: Multi Variable Calculus | BD3: Data Structures | BG3: Computer Organization & Assembly Language | BJ3: Introduction to Artificial Intelligence | BM3: Computer Network | BT3: Probability & Statistics | CA3: Design Analysis of Algorithms | CG3: Data Structures and Algorithms | CK3: Applied Statistics | CP3: Software Engineering | CS3: World History | CV3: Artificial Intelligence | DA3: Data Communication & Computer Networks | DF3: Continuous Discreate Optimization | DK3: Data Base Management Systems | DQ3: Introduction to Python Lab | DX3: World Literature | EE3: Machine Learning | EJ3: Computer Vision | EP3: Parallel and Distributed Computing | EV3: Academic & Professional Writing | EY3: Logical And Automated Reasoning | FB3: Data Visualization | FH3: Artificial Intelligence | FM3: Philosophy and Critical Thinking | FO3: Natural Language Processing | FT3: Final Year Project - I | GF3: Logical And Automated Reasoning | GJ3: Philosophy and Critical Thinking | GN3: Deep Learning | GS3: Artificial Intelligence for Robotics | GX3: Sociology | HA3: Ethics and Social Responsibility | HD3: Philosophy and Critical Thinking | HH3: Final Year Project - II
E4: CLO 1 | F4: CLO 2 | G4: CLO 3 | H4: CLO 1 | I4: CLO 2 | J4: CLO 3 | K4: CLO 1 | L4: CLO 2 | M4: CLO 3 | N4: CLO 1 | O4: CLO 2 | P4: CLO 1 | Q4: CLO 2 | R4: CLO 3 | S4: CLO1 | T4: CLO2 | U4: CLO 1 | V4: CLO 2 | W4: CLO 3 | X4: CLO 3 | Y4: CLO 1 | Z4: CLO 2 | AA4: CLO 3 | AB4: CLO 4 | AE4: CLO 1 | AF4: CLO 2 | AG4: CLO 1 | AH4: CLO 2 | AI4: CLO 3 | AJ4: CLO 4 | AK4: CLO 1 | AL4: CLO 2 | AM4: CLO 1 | AN4: CLO 2 | AO4: CLO 3 | AP4: CLO 1 | AQ4: CLO 2 | AR4: CLO 3 | AS4: CLO4 | AT4: CLO5 | AU4: CLO 1 | AV4: CLO 2 | AW4: CLO 3 | AX4: CLO 5 | AY4: CLO 4 | AZ4: CLO 1 | BA4: CLO 2 | BB4: CLO 3 | BC4: CLO 4 | BD4: CLO 1 | BE4: CLO 2 | BF4: CLO 3 | BG4: CLO 1 | BH4: CLO 2 | BI4: CLO 3 | BJ4: CLO 1 | BK4: CLO 2 | BL4: CLO 3 | BM4: CLO 1 | BN4: CLO 2 | BO4: CLO 3 | BP4: CLO 4 | BQ4: CLO 5 | BR4: CLO 6 | BS4: CLO 7 | BT4: CLO 1 | BU4: CLO 2 | BV4: CLO 3 | BW4: CLO 4 | BX4: CLO 5 | BY4: CLO 1 | BZ4: CLO 2 | CA4: CLO 1 | CB4: CLO 2 | CC4: CLO 3 | CD4: CLO 4 | CE4: CLO 5 | CF4: CLO 6 | CG4: CLO 1 | CH4: CLO 2 | CI4: CLO 3 | CJ4: CLO 4 | CK4: CLO 1 | CL4: CLO 2 | CM4: CLO 3 | CN4: CLO 1 | CO4: CLO 2 | CP4: CLO 1 | CQ4: CLO 2 | CR4: CLO 3 | CS4: CLO 1 | CT4: CLO 2 | CU4: CLO 3 | CV4: CLO1 | CW4: CLO2 | CX4: CLO 3 | CY4: CLO 1 | CZ4: CLO 2 | DA4: CLO 1 | DB4: CLO 2 | DC4: CLO 3 | DD4: CLO 1 | DE4: CLO 2 | DF4: CLO1 | DG4: CLO2 | DH4: CLO3 | DI4: CLO1 | DJ4: CLO2 | DK4: CLO1 | DL4: CLO2 | DM4: CLO3 | DN4: CLO4 | DO4: CLO1 | DP4: CLO2 | DQ4: CLO1 | DR4: CLO2 | DS4: CLO3 | DT4: CLO4 | DU4: CLO5 | DV4: CLO6 | DW4: CLO7 | DX4: CLO1 | DY4: CLO2 | DZ4: CLO3 | EA4: CLO4 | EB4: CLO5 | EC4: CLO6 | ED4: CLO7 | EE4: CLO1 | EF4: CLO2 | EG4: CLO3 | EH4: CLO1 | EI4: CLO2 | EJ4: CLO1 | EK4: CLO2 | EL4: CLO3 | EM4: CLO4 | EN4: CLO5 | EO4: CLO6 | EP4: CLO1 | EQ4: CLO 2 | ER4: CLO 3 | ES4: CLO 4 | EU4: CLO3 | EV4: CLO1 | EW4: CLO2 | EX4: CLO7 | EY4: CLO1 | EZ4: CLO2 | FA4: CLO3 | FB4: CLO1 | FC4: CLO2 | FD4: CLO3 | FE4: CLO4 | FF4: CLO 1 | FG4: CLO 2 | FH4: CLO1 | FI4: CLO2 | FJ4: CLO 3 | FK4: CLO 1 | FL4: CLO 2 | FM4: CLO1 | FN4: CLO2 | FO4: CLO1 | FP4: CLO2 | FQ4: CLO3 | FR4: CLO 1 | FS4: CLO 2 | FT4: R1 | FU4: R2 | FV4: R3 | FW4: R4 | FX4: R5 | FY4: R6 | FZ4: R7 | GA4: R8 | GB4: R9 | GC4: R10 | GD4: R11 | GE4: R12 | GF4: CLO 1 | GG4: CLO 2 | GH4: CLO 3 | GI4: CLO 4 | GN4: CLO1 | GO4: CLO 2 | GP4: CLO 3 | GQ4: CLO 1 | GR4: CLO 2 | GS4: CLO1 | GT4: CLO2 | GU4: CLO3 | GV4: CLO 1 | GW4: CLO 2 | GX4: CLO1 | GY4: CLO2 | GZ4: CLO3 | HA4: CLO1 | HB4: CLO2 | HC4: CLO3 | HH4: R1 | HI4: R2 | HJ4: R3 | HK4: R4 | HL4: R5 | HM4: R6 | HN4: R7 | HO4: R8 | HP4: R9 | HQ4: R10 | HR4: R11 | HS4: R12 | HU4: GA1 | HV4: GA2 | HW4: GA3 | HX4: GA4 | HY4: GA5 | HZ4: GA6 | IA4: GA7 | IB4: GA8 | IC4: GA9 | ID4: GA10
E5: Theory | H5: Lab | K5: Theory | N5: Lab | P5: Theory | S5: Lab | U5: Theory | Y5: Theory | AK5: Lab | BU5: Theory | BY5: Lab | CI5: Lab | CK5: Theory | CN5: Lab | CP5: GA 2 | CQ5: GA 3 | CR5: GA 5 | CV5: Theory | CY5: Lab | DA5: Theory | DD5: Lab | DF5: Theory | DI5: Lab | DK5: Theory | DO5: Lab | EE5: Theory | EH5: Lab | EP5: Theory | ET5: Lab | EY5: Theory | FB5: Theory | FF5: Lab | FH5: Theory | FK5: Lab | FO5: Theory | FR5: Lab | GN5: Theory | GQ5: Lab | GS5: Theory | GV5: Lab
E6: GA2 | F6: GA 2 | G6: GA5 | H6: GA7 | I6: GA 2 | J6: GA6 | K6: GA1 | L6: GA 2 | M6: GA2 | N6: GA1 | P6: GA 1 | Q6: GA 2 | R6: GA 4 | S6: GA 2 | T6: GA 5 | U6: GA 1 | V6: GA 2 | W6: GA 3 | X6: GA 4 | Y6: GA 5 | Z6: GA 5 | AA6: GA 7 | AB6: GA 2 | AE6: GA10 | AG6: GA 2 | AI6: GA 4 | AK6: GA 4 | AL6: GA 5 | AM6: GA1 | AP6: GA1 | AQ6: GA 2 | AU6: GA1 | AY6: GA4 | AZ6: GA1 | BA6: GA2 | BB6: GA1 | BC6: GA2 | BD6: GA5 | BF6: GA1 | BG6: GA2 | BI6: GA4 | BJ6: GA6 | BK6: GA7 | BL6: GA8 | BM6: GA1 | BR6: GA8 | BS6: GA10 | BT6: GA1 | BU6: GA2 | BW6: GA 5 | BY6: GA 2 | BZ6: GA5 | CA6: GA2 | CB6: GA3 | CC6: GA2 | CD6: GA4 | CE6: GA8 | CF6: GA10 | CG6: GA 2 | CH6: GA 5 | CI6: GA 2 | CJ6: GA 3 | CK6: GA2 | CL6: GA3 | CM6: GA5 | CN6: GA8 | CO6: GA10 | CP6: PLO10 | CQ6: PLO9 | CR6: PLO5 | CS6: PLO1 | CU6: PLO3 | CV6: GA 1 | CW6: GA 2 | CX6: GA 3 | CY6: GA 4 | CZ6: GA 5 | DA6: GA2 | DB6: GA3 | DC6: GA5 | DD6: GA8 | DE6: GA10 | DF6: GA 1 | DG6: GA 2 | DH6: GA 5 | DI6: GA 5 | DK6: GA 1 | DL6: GA 3 | DM6: GA 4 | DN6: GA 5 | DO6: GA 4 | DQ6: PLO2 | DT6: PLO3 | DU6: PLO5 | DV6: PLO8 | DW6: PLO10 | DX6: PLO2 | DZ6: PLO3 | EA6: PLO5 | EB6: PLO1 | EC6: PLO8 | ED6: PLO10 | EE6: GA 1 | EF6: GA 3 | EH6: GA 1 | EI6: GA 3 | EJ6: PLO1 | EK6: PLO3 | EL6: PLO2 | EM6: PLO5 | EN6: PLO8 | EO6: PLO10 | EP6: GA 1 | EQ6: GA 2 | ER6: GA 3 | ES6: GA 4 | EV6: GA 1 | EW6: GA 7 | EX6: GA 8 | EY6: GA 1 | EZ6: GA 2 | FA6: GA 9 | FB6: GA2 | FC6: GA 2 | FD6: GA 3 | FE6: GA 5 | FF6: GA 3 | FG6: GA 4 | FH6: GA 1 | FI6: GA 2 | FJ6: GA 3 | FK6: GA 4 | FL6: GA 5 | FM6: PLO4 | FN6: PLO5 | FO6: GA 1 | FP6: GA 2 | FQ6: GA 3 | FR6: GA 1 | FS6: GA 3 | FT6: GA1 | FU6: GA2 | FV6: GA3 | FW6: GA4 | FX6: GA5 | FY6: GA6 | FZ6: GA7 | GA6: GA8 | GB6: GA9 | GC6: GA10 | GD6: GA11 | GE6: GA12 | GN6: GA 1 | GO6: GA 3 | GQ6: GA 1 | GR6: GA 3 | GS6: GA 1 | GT6: GA 2 | GU6: GA 5 | GV6: GA 5 | GX6: PLO1 | HA6: PLO1 | HB6: PLO2 | HC6: PLO5 | HH6: GA1 | HI6: GA2 | HJ6: GA3 | HK6: GA4 | HL6: GA5 | HM6: GA6 | HN6: GA7 | HO6: GA8 | HP6: GA9 | HQ6: GA10 | HR6: GA11 | HS6: GA12
B7: 1 | C7: 052-25-26075 | D7: Wahaj Nawaz Khan | E7: 0 | F7: 0 | G7: 0 | H7: 0 | I7: 0 | J7: 0 | K7: 0 | L7: 0 | M7: 0 | N7: 83.92 | P7: 68 | Q7: 56.11 | R7: 50 | S7: 67.27 | T7: 83.33 | U7: 0 | V7: 0 | W7: 0 | X7: 0 | Y7: 0 | Z7: 0 | AA7: 0 | AB7: 0 | HU7: =AVERAGE(H7,N7,P7) | HV7: =AVERAGE(E7,J7,Q7,S7,U7,Y7,AD7) | HW7: =AVERAGE(V7) | HX7: =AVERAGE(R7) | HY7: =AVERAGE(Z7,T7,G7) | IA7: =AVERAGE(AB7) | ID7: =AVERAGE(AC7)
B8: 2 | C8: 052-25-27216 | D8: Muhammad Hamza Abbasi | E8: 76.67 | F8: 83.5 | G8: 79.44 | H8: 79.67 | I8: 80.95 | J8: 80 | K8: 83.33 | L8: 88.89 | M8: 67.94 | N8: 90.33 | P8: 77.78 | Q8: 77.78 | R8: 51.11 | S8: 79.39 | T8: 82.88 | U8: 65 | V8: 58.33 | W8: 66.67 | X8: 100 | Y8: 91.25 | Z8: 80.67 | AA8: 83.33 | AB8: 85 | HU8: =AVERAGE(H8,N8,P8) | HV8: =AVERAGE(E8,J8,Q8,S8,U8,Y8,AD8) | HW8: =AVERAGE(V8) | HX8: =AVERAGE(R8) | HY8: =AVERAGE(Z8,T8,G8) | IA8: =AVERAGE(AB8) | ID8: =AVERAGE(AC8)
B9: 3 | C9: 052-25-27217 | D9: Fasih Rathiyal | E9: 81.33 | F9: 81 | G9: 78.89 | H9: 78.67 | I9: 84.29 | J9: 78.33 | K9: 83.5 | L9: 73.61 | M9: 60.58 | N9: 81.1 | P9: 64 | Q9: 70.56 | R9: 50.56 | S9: 61.52 | T9: 59.55 | U9: 64.44 | V9: 59.17 | W9: 91.67 | X9: 100 | Y9: 88.75 | Z9: 74 | AA9: 86.67 | AB9: 90 | HU9: =AVERAGE(H9,N9,P9) | HV9: =AVERAGE(E9,J9,Q9,S9,U9,Y9,AD9) | HW9: =AVERAGE(V9) | HX9: =AVERAGE(R9) | HY9: =AVERAGE(Z9,T9,G9) | IA9: =AVERAGE(AB9) | ID9: =AVERAGE(AC9)
B10: 4 | C10: 052-25-27221 | D10: Haider Ali | E10: 78 | F10: 81.5 | G10: 78.89 | H10: 77.67 | I10: 75.24 | J10: 78.33 | K10: 66.5 | L10: 78.33 | M10: 51.69 | N10: 86.58 | P10: 50 | Q10: 61.11 | R10: 57.78 | S10: 66.67 | T10: 75.91 | U10: 47.78 | V10: 30 | W10: 0 | X10: 0 | Y10: 83.75 | Z10: 78 | AA10: 80 | AB10: 90 | HU10: =AVERAGE(H10,N10,P10) | HV10: =AVERAGE(E10,J10,Q10,S10,U10,Y10,AD10) | HW10: =AVERAGE(V10) | HX10: =AVERAGE(R10) | HY10: =AVERAGE(Z10,T10,G10) | IA10: =AVERAGE(AB10) | ID10: =AVERAGE(AC10)
B11: 5 | C11: 052-25-27224 | D11: Sadia Imran | E11: 84.67 | F11: 81.75 | G11: 83.89 | H11: 86 | I11: 81.9 | J11: 86.67 | K11: 70.33 | L11: 70.83 | M11: 58.5 | N11: 90.9 | P11: 96 | Q11: 90.56 | R11: 83.89 | S11: 86.97 | T11: 91.21 | U11: 65.56 | V11: 58.33 | W11: 25 | X11: 75 | Y11: 96.25 | Z11: 92 | AA11: 90 | AB11: 90 | HU11: =AVERAGE(H11,N11,P11) | HV11: =AVERAGE(E11,J11,Q11,S11,U11,Y11,AD11) | HW11: =AVERAGE(V11) | HX11: =AVERAGE(R11) | HY11: =AVERAGE(Z11,T11,G11) | IA11: =AVERAGE(AB11) | ID11: =AVERAGE(AC11)
B12: 6 | C12: 052-25-27229 | D12: Muhammad Haider Iqbal | E12: 66.67 | F12: 76.25 | G12: 73.89 | H12: 73.33 | I12: 75.71 | J12: 73.33 | K12: 74.67 | L12: 79.72 | M12: 63.22 | N12: 20.42 | P12: 18 | Q12: 26.67 | R12: 15 | S12: 21.21 | T12: 9.09 | U12: 57.78 | V12: 65 | W12: 25 | X12: 75 | Y12: 96.25 | Z12: 82.67 | AA12: 93.33 | AB12: 90 | HU12: =AVERAGE(H12,N12,P12) | HV12: =AVERAGE(E12,J12,Q12,S12,U12,Y12,AD12) | HW12: =AVERAGE(V12) | HX12: =AVERAGE(R12) | HY12: =AVERAGE(Z12,T12,G12) | IA12: =AVERAGE(AB12) | ID12: =AVERAGE(AC12)
B13: 7 | C13: 052-25-27252 | D13: Hifza Noor | E13: 85.33 | F13: 83.5 | G13: 78.89 | H13: 84.33 | I13: 85.71 | J13: 87.78 | K13: 78.5 | L13: 85 | M13: 72.53 | N13: 89.66 | P13: 74 | Q13: 60 | R13: 60.56 | S13: 77.27 | T13: 84.55 | U13: 67.22 | V13: 67.5 | W13: 58.33 | X13: 25 | Y13: 81.25 | Z13: 70.67 | AA13: 83.33 | AB13: 85 | HU13: =AVERAGE(H13,N13,P13) | HV13: =AVERAGE(E13,J13,Q13,S13,U13,Y13,AD13) | HW13: =AVERAGE(V13) | HX13: =AVERAGE(R13) | HY13: =AVERAGE(Z13,T13,G13) | IA13: =AVERAGE(AB13) | ID13: =AVERAGE(AC13)
B14: 8 | C14: 052-25-27262 | D14: Usman Khan | E14: 38.67 | F14: 51 | G14: 46.11 | H14: 49 | I14: 52.38 | J14: 53.33 | K14: 70.33 | L14: 79.17 | M14: 61.86 | N14: 51.11 | P14: 72 | Q14: 60 | R14: 58.89 | S14: 62.73 | T14: 73.18 | U14: 41.11 | V14: 37.5 | W14: 8.33 | X14: 50 | Y14: 82.5 | Z14: 68 | AA14: 83.33 | AB14: 85 | HU14: =AVERAGE(H14,N14,P14) | HV14: =AVERAGE(E14,J14,Q14,S14,U14,Y14,AD14) | HW14: =AVERAGE(V14) | HX14: =AVERAGE(R14) | HY14: =AVERAGE(Z14,T14,G14) | IA14: =AVERAGE(AB14) | ID14: =AVERAGE(AC14)
B15: 9 | C15: 052-25-27270 | D15: Fasih Ur Rehman | E15: 85.33 | F15: 85.5 | G15: 84.44 | H15: 83.33 | I15: 84.76 | J15: 87.22 | K15: 74.33 | L15: 81.94 | M15: 67.11 | N15: 88.32 | P15: 74 | Q15: 90.56 | R15: 73.33 | S15: 84.85 | T15: 78.18 | U15: 68.33 | V15: 78.33 | W15: 16.67 | X15: 100 | Y15: 76.25 | Z15: 76.67 | AA15: 90 | AB15: 85 | HU15: =AVERAGE(H15,N15,P15) | HV15: =AVERAGE(E15,J15,Q15,S15,U15,Y15,AD15) | HW15: =AVERAGE(V15) | HX15: =AVERAGE(R15) | HY15: =AVERAGE(Z15,T15,G15) | IA15: =AVERAGE(AB15) | ID15: =AVERAGE(AC15)
B16: 10 | C16: 052-25-27273 | D16: Muhammad Arslan | E16: 67.33 | F16: 79.5 | G16: 83.89 | H16: 84.67 | I16: 76.67 | J16: 83.33 | K16: 75.17 | L16: 74.44 | M16: 54.61 | N16: 85.74 | P16: 72 | Q16: 51.67 | R16: 51.11 | S16: 76.97 | T16: 80 | U16: 52.22 | V16: 54.17 | W16: 50 | X16: 50 | Y16: 87.5 | Z16: 80 | AA16: 83.33 | AB16: 90 | HU16: =AVERAGE(H16,N16,P16) | HV16: =AVERAGE(E16,J16,Q16,S16,U16,Y16,AD16) | HW16: =AVERAGE(V16) | HX16: =AVERAGE(R16) | HY16: =AVERAGE(Z16,T16,G16) | IA16: =AVERAGE(AB16) | ID16: =AVERAGE(AC16)
B17: 11 | C17: 052-25-27286 | D17: Sajjad Hussain | E17: 64 | F17: 67.5 | G17: 68.33 | H17: 63.33 | I17: 72.38 | J17: 71.67 | K17: 96 | L17: 92.22 | M17: 57 | N17: 91.72 | P17: 94 | Q17: 92.22 | R17: 91.11 | S17: 90.61 | T17: 97.58 | U17: 41.11 | V17: 29.17 | W17: 0 | X17: 0 | Y17: 80 | Z17: 76 | AA17: 76.67 | AB17: 85 | HU17: =AVERAGE(H17,N17,P17) | HV17: =AVERAGE(E17,J17,Q17,S17,U17,Y17,AD17) | HW17: =AVERAGE(V17) | HX17: =AVERAGE(R17) | HY17: =AVERAGE(Z17,T17,G17) | IA17: =AVERAGE(AB17) | ID17: =AVERAGE(AC17)
B18: 12 | C18: 052-25-27301 | D18: Abdar Hussain | E18: 64.67 | F18: 60.5 | G18: 58.33 | H18: 61 | I18: 58.57 | J18: 62.22 | K18: 75.83 | L18: 74.44 | M18: 69.19 | N18: 81.64 | P18: 90 | Q18: 91.67 | R18: 80 | S18: 87.88 | T18: 80.91 | U18: 55 | V18: 46.67 | W18: 25 | X18: 50 | Y18: 90 | Z18: 83.33 | AA18: 83.33 | AB18: 90 | HU18: =AVERAGE(H18,N18,P18) | HV18: =AVERAGE(E18,J18,Q18,S18,U18,Y18,AD18) | HW18: =AVERAGE(V18) | HX18: =AVERAGE(R18) | HY18: =AVERAGE(Z18,T18,G18) | IA18: =AVERAGE(AB18) | ID18: =AVERAGE(AC18)
... B26: 20 | C26: 052-25-27441 | D26: Atif Ullah | E26: 65.33 | F26: 64.25 | G26: 68.33 | H26: 64.33 | I26: 62.39 | J26: 65.56 | K26: 76.67 | L26: 65.56 | M26: 65.11 | N26: 26.78 | P26: 50 | Q26: 13.33 | R26: 21.67 | S26: 63.03 | T26: 64.24 | U26: 52.78 | V26: 43.33 | W26: 33.33 | X26: 50 | Y26: 83.75 | Z26: 76.67 | AA26: 73.33 | AB26: 90 | HU26: =AVERAGE(H26,N26,P26) | HV26: =AVERAGE(E26,J26,Q26,S26,U26,Y26,AD26) | HW26: =AVERAGE(V26) | HX26: =AVERAGE(R26) | HY26: =AVERAGE(Z26,T26,G26) | IA26: =AVERAGE(AB26) | ID26: =AVERAGE(AC26)
B27: Class Average | E27: =AVERAGE(E7:E25) | F27: =AVERAGE(F7:F25) | G27: =AVERAGE(G7:G25) | H27: =AVERAGE(H7:H25) | I27: =AVERAGE(I7:I25) | J27: =AVERAGE(J7:J25) | K27: =AVERAGE(K7:K25) | L27: =AVERAGE(L7:L25) | ... N27: =AVERAGE(N7:N25) | P27: =AVERAGE(P7:P25) | Q27: =AVERAGE(Q7:Q25) | R27: =AVERAGE(R7:R25) | S27: =AVERAGE(S7:S25) | T27: =AVERAGE(T7:T25) | U27: =AVERAGE(U7:U25) | V27: =AVERAGE(V7:V25) | W27: =AVERAGE(W7:W25) | ... AQ27: =AVERAGE(AQ7:AQ25) | AU27: =AVERAGE(AU7:AU25) | AV27: =AVERAGE(AV7:AV25) | AW27: =AVERAGE(AW7:AW25) | AX27: =AVERAGE(AX7:AX25) | AY27: =AVERAGE(AY7:AY25) | AZ27: =AVERAGE(AZ7:AZ25) | BA27: =AVERAGE(BA7:BA25) | BB27: =AVERAGE(BB7:BB25) | ... ET27: =AVERAGE(ET7:ET25) | EV27: =AVERAGE(EV7:EV25) | EW27: =AVERAGE(EW7:EW25) | EX27: =AVERAGE(EX7:EX25) | EY27: =AVERAGE(EY7:EY25) | EZ27: =AVERAGE(EZ7:EZ25) | FA27: =AVERAGE(FA7:FA25) | FB27: =AVERAGE(FB7:FB25) | FD27: =AVERAGE(FD7:FD25) | FE27: =AVERAGE(FE7:FE25) | FF27: =AVERAGE(FF7:FF25) | FG27: =AVERAGE(FG7:FG25) | FH27: =AVERAGE(FH7:FH25) | FI27: =AVERAGE(FI7:FI25) | FJ27: =AVERAGE(FJ7:FJ25) | FK27: =AVERAGE(FK7:FK25) | ... HS27: =AVERAGE(HS7:HS25) | HU27: =AVERAGE(HU7:HU26) | HV27: =AVERAGE(HV7:HV26) | HW27: =AVERAGE(HW7:HW26) | HX27: =AVERAGE(HX7:HX26) | HY27: =AVERAGE(HY7:HY26) | IA27: =AVERAGE(IA7:IA26) | ID27: =AVERAGE(ID7:ID26)

Sheet AI-SP-25
A1: Batch Spring 2025 | CQ1: Assessment of GA's | HO1: Attainment of GAs | HP1: Attainment of Graduate Attribute
B2: Sr. No. | D2: Student Name | E2: Semester 1 | AA2: Semester 2 | AY2: Semester 3 | BV2: Semester 4 | CQ2: Semester 5 | DZ2: Semester 6 | FC2: Semester 7 | GI2: Semester - 8
E3: Application of information & Communication Technologies | I3: Applied Physics | N3: Programming Fundamentals | S3: Calculus and Analytic Geometry | V3: Functional English | Y3: Islamic Studies | AA3: Expository Writing | AD3: Object Oriented Programming | AK3: Discreate Structures | AL3: Ideology and Constitution of Pakistan | AN3: Digital Logic Design | AU3: Multi Variable Calculus | AY3: Data Structures | BB3: Computer Organization & Assembly Language | BE3: Introduction to Artificial Intelligence | BH3: Computer Network | BO3: Probability & Statistics | BV3: Design Analysis of Algorithms | CB3: Data Structures and Algorithms | CF3: Applied Statistics | CK3: Software Engineering | CN3: World History | CQ3: Artificial Intelligence | CV3: Data Communication & Computer Networks | DA3: Continuous Discreate Optimization | DF3: Data Base Management Systems | DL3: Introduction to Python Lab | DS3: World Literature | DZ3: Machine Learning | EE3: Computer Vision | EK3: Parallel and Distributed Computing | EQ3: Academic & Professional Writing | ET3: Logical And Automated Reasoning | EW3: Data Visualization | FC3: Artificial Intelligence | FH3: Philosophy and Critical Thinking | FJ3: Natural Language Processing | FO3: Final Year Project - I | GA3: Logical And Automated Reasoning | GE3: Philosophy and Critical Thinking | GI3: Deep Learning | GN3: Artificial Intelligence for Robotics | GS3: Sociology | GV3: Ethics and Social Responsibility | GY3: Philosophy and Critical Thinking | HC3: Final Year Project - II
E4: CLO 1 | F4: CLO 2 | G4: CLO 1 | H4: CLO 2 | I4: CLO 1 | J4: CLO 2 | K4: CLO 3 | L4: CLO 1 | M4: CLO 2 | N4: CLO 1 | O4: CLO 2 | P4: CLO 3 | Q4: CLO1 | R4: CLO2 | S4: CLO 1 | T4: CLO 2 | U4: CLO 3 | V4: CLO 1 | W4: CLO 2 | X4: CLO 4 | Y4: CLO 1 | Z4: CLO 3 | AA4: CLO 1 | AB4: CLO 2 | AC4: CLO 3 | AD4: CLO 1 | AE4: CLO 2 | AF4: CLO 3 | AG4: CLO 1 | AH4: CLO 1 | AI4: CLO 2 | AJ4: CLO 3 | AK4: CLO 3 | AL4: CLO 1 | AM4: CLO 2 | AN4: CLO 1 | AO4: CLO 2 | AP4: CLO 3 | AQ4: CLO 1 | AR4: CLO 2 | AS4: CLO 3 | AT4: CLO 4 | AU4: CLO 1 | AV4: CLO 2 | AW4: CLO 3 | AX4: CLO 4 | AY4: CLO 1 | AZ4: CLO 2 | BA4: CLO 3 | BB4: CLO 1 | BC4: CLO 2 | BD4: CLO 3 | BE4: CLO 1 | BF4: CLO 2 | BG4: CLO 3 | BH4: CLO 1 | BI4: CLO 2 | BJ4: CLO 3 | BK4: CLO 4 | BL4: CLO 5 | BM4: CLO 6 | BN4: CLO 7 | BO4: CLO 1 | BP4: CLO 2 | BQ4: CLO 3 | BR4: CLO 4 | BS4: CLO 5 | BT4: CLO 1 | BU4: CLO 2 | BV4: CLO 1 | BW4: CLO 2 | BX4: CLO 3 | BY4: CLO 4 | BZ4: CLO 5 | CA4: CLO 6 | CB4: CLO 1 | CC4: CLO 2 | CD4: CLO 3 | CE4: CLO 4 | CF4: CLO 1 | CG4: CLO 2 | CH4: CLO 3 | CI4: CLO 1 | CJ4: CLO 2 | CK4: CLO 1 | CL4: CLO 2 | CM4: CLO 3 | CN4: CLO 1 | CO4: CLO 2 | CP4: CLO 3 | CQ4: CLO1 | CR4: CLO2 | CS4: CLO 3 | CT4: CLO 1 | CU4: CLO 2 | CV4: CLO 1 | CW4: CLO 2 | CX4: CLO 3 | CY4: CLO 1 | CZ4: CLO 2 | DA4: CLO1 | DB4: CLO2 | DC4: CLO3 | DD4: CLO1 | DE4: CLO2 | DF4: CLO1 | DG4: CLO2 | DH4: CLO3 | DI4: CLO4 | DJ4: CLO1 | DK4: CLO2 | DL4: CLO1 | DM4: CLO2 | DN4: CLO3 | DO4: CLO4 | DP4: CLO5 | DQ4: CLO6 | DR4: CLO7 | DS4: CLO1 | DT4: CLO2 | DU4: CLO3 | DV4: CLO4 | DW4: CLO5 | DX4: CLO6 | DY4: CLO7 | DZ4: CLO1 | EA4: CLO2 | EB4: CLO3 | EC4: CLO1 | ED4: CLO2 | EE4: CLO1 | EF4: CLO2 | EG4: CLO3 | EH4: CLO4 | EI4: CLO5 | EJ4: CLO6 | EK4: CLO1 | EL4: CLO 2 | EM4: CLO 3 | EN4: CLO 4 | EP4: CLO3 | EQ4: CLO1 | ER4: CLO2 | ES4: CLO7 | ET4: CLO1 | EU4: CLO2 | EV4: CLO3 | EW4: CLO1 | EX4: CLO2 | EY4: CLO3 | EZ4: CLO4 | FA4: CLO 1 | FB4: CLO 2 | FC4: CLO1 | FD4: CLO2 | FE4: CLO 3 | FF4: CLO 1 | FG4: CLO 2 | FH4: CLO1 | FI4: CLO2 | FJ4: CLO1 | FK4: CLO2 | FL4: CLO3 | FM4: CLO 1 | FN4: CLO 2 | FO4: R1 | FP4: R2 | FQ4: R3 | FR4: R4 | FS4: R5 | FT4: R6 | FU4: R7 | FV4: R8 | FW4: R9 | FX4: R10 | FY4: R11 | FZ4: R12 | GA4: CLO 1 | GB4: CLO 2 | GC4: CLO 3 | GD4: CLO 4 | GI4: CLO1 | GJ4: CLO 2 | GK4: CLO 3 | GL4: CLO 1 | GM4: CLO 2 | GN4: CLO1 | GO4: CLO2 | GP4: CLO3 | GQ4: CLO 1 | GR4: CLO 2 | GS4: CLO1 | GT4: CLO2 | GU4: CLO3 | GV4: CLO1 | GW4: CLO2 | GX4: CLO3 | HC4: R1 | HD4: R2 | HE4: R3 | HF4: R4 | HG4: R5 | HH4: R6 | HI4: R7 | HJ4: R8 | HK4: R9 | HL4: R10 | HM4: R11 | HN4: R12 | HP4: GA1 | HQ4: GA2 | HR4: GA3 | HS4: GA4 | HT4: GA5 | HU4: GA6 | HV4: GA7 | HW4: GA8 | HX4: GA9 | HY4: GA10
E5: Theory | G5: Lab | I5: Theory | L5: Lab | N5: Theory | Q5: Lab | V5: Theory | Y5: Theory | AA5: Theory | AD5: Theory | AH5: Lab | AL5: Theory | AN5: Theory | AQ5: Lab | AU5: Theory | BP5: Theory | BT5: Lab | CD5: Lab | CF5: Theory | CI5: Lab | CK5: GA 2 | CL5: GA 3 | CM5: GA 5 | CQ5: Theory | CT5: Lab | CV5: Theory | CY5: Lab | DA5: Theory | DD5: Lab | DF5: Theory | DJ5: Lab | DZ5: Theory | EC5: Lab | EK5: Theory | EO5: Lab | ET5: Theory | EW5: Theory | FA5: Lab | FC5: Theory | FF5: Lab | FJ5: Theory | FM5: Lab | GI5: Theory | GL5: Lab | GN5: Theory | GQ5: Lab
E6: GA2 | F6: GA5 | G6: GA1 | H6: GA2 | I6: GA1 | L6: GA1 | N6: GA 1 | O6: GA 2 | P6: GA 4 | Q6: GA 2 | R6: GA 5 | S6: GA 2 | T6: GA 3 | U6: GA 3 | V6: GA 2 | W6: GA 5 | X6: GA 7 | Y6: GA10 | Z6: GA2 | AA6: GA1 | AB6: GA3 | AC6: GA3 | AD6: GA 1 | AE6: GA 2 | AF6: GA 3 | AG6: GA 4 | AH6: GA 2 | AI6: GA 5 | AJ6: GA 6 | AK6: GA 3 | AL6: GA1 | AM6: GA 2 | AN6: GA 2 | AO6: GA 2 | AP6: GA 3 | AQ6: GA1 | AR6: GA6 | AS6: GA7 | AT6: GA9 | AU6: GA1 | AV6: GA2 | AW6: GA 3 | AX6: GA 4 | AY6: GA5 | BA6: GA1 | BB6: GA2 | BD6: GA4 | BE6: GA6 | BF6: GA7 | BG6: GA8 | BH6: GA1 | BM6: GA8 | BN6: GA10 | BO6: GA1 | BP6: GA2 | BR6: GA 5 | BT6: GA 2 | BU6: GA5 | BV6: GA2 | BW6: GA3 | BX6: GA2 | BY6: GA4 | BZ6: GA8 | CA6: GA10 | CB6: GA 2 | CC6: GA 5 | CD6: GA 2 | CE6: GA 3 | CF6: GA2 | CG6: GA3 | CH6: GA5 | CI6: GA8 | CJ6: GA10 | CK6: PLO10 | CL6: PLO9 | CM6: PLO5 | CN6: PLO1 | CP6: PLO3 | CQ6: GA 1 | CR6: GA 2 | CS6: GA 3 | CT6: GA 4 | CU6: GA 5 | CV6: GA2 | CW6: GA3 | CX6: GA5 | CY6: GA8 | CZ6: GA10 | DA6: GA 1 | DB6: GA 2 | DC6: GA 5 | DD6: GA 5 | DF6: GA 1 | DG6: GA 3 | DH6: GA 4 | DI6: GA 5 | DJ6: GA 4 | DL6: PLO2 | DO6: PLO3 | DP6: PLO5 | DQ6: PLO8 | DR6: PLO10 | DS6: PLO2 | DU6: PLO3 | DV6: PLO5 | DW6: PLO1 | DX6: PLO8 | DY6: PLO10 | DZ6: GA 1 | EA6: GA 3 | EC6: GA 1 | ED6: GA 3 | EE6: PLO1 | EF6: PLO3 | EG6: PLO2 | EH6: PLO5 | EI6: PLO8 | EJ6: PLO10 | EK6: GA 1 | EL6: GA 2 | EM6: GA 3 | EN6: GA 4 | EQ6: GA 1 | ER6: GA 7 | ES6: GA 8 | ET6: GA 1 | EU6: GA 2 | EV6: GA 9 | EW6: GA2 | EX6: GA 2 | EY6: GA 3 | EZ6: GA 5 | FA6: GA 3 | FB6: GA 4 | FC6: GA 1 | FD6: GA 2 | FE6: GA 3 | FF6: GA 4 | FG6: GA 5 | FH6: PLO4 | FI6: PLO5 | FJ6: GA 1 | FK6: GA 2 | FL6: GA 3 | FM6: GA 1 | FN6: GA 3 | FO6: GA1 | FP6: GA2 | FQ6: GA3 | FR6: GA4 | FS6: GA5 | FT6: GA6 | FU6: GA7 | FV6: GA8 | FW6: GA9 | FX6: GA10 | FY6: GA11 | FZ6: GA12 | GI6: GA 1 | GJ6: GA 3 | GL6: GA 1 | GM6: GA 3 | GN6: GA 1 | GO6: GA 2 | GP6: GA 5 | GQ6: GA 5 | GS6: PLO1 | GV6: PLO1 | GW6: PLO2 | GX6: PLO5 | HC6: GA1 | HD6: GA2 | HE6: GA3 | HF6: GA4 | HG6: GA5 | HH6: GA6 | HI6: GA7 | HJ6: GA8 | HK6: GA9 | HL6: GA10 | HM6: GA11 | HN6: GA12
B7: 1 | C7: 052-25-126005 | D7: Naveed ul Hassan | E7: 81.67 | F7: 73.33 | G7: 79.63 | H7: 85.76 | I7: 57.983333 | L7: 83.92 | N7: 68 | O7: 56.11 | P7: 50 | Q7: 67.27 | R7: 83.33 | S7: 92.5 | T7: 89.17 | V7: 75.36 | W7: 75.35 | X7: 100 | Y7: 64.44 | Z7: 74 | AA7: 63.75 | AB7: 50 | AC7: 71.11 | AD7: 0 | AE7: 30 | AF7: 3.3333333 | AG7: 0 | AH7: 35 | AI7: 30 | AJ7: 16 | AK7: 51.51 | AN7: 30.48 | AO7: 4.17 | AP7: 0 | AQ7: 40.3 | AR7: 40.24 | AS7: 32 | AT7: 40 | AU7: 28.75 | AV7: 42.5 | AW7: 8.33 | AX7: 50 | HP7: =AVERAGE(G7,L7,N7) | HQ7: =AVERAGE(E7,H7,O7,Q7,S7,V7,Z7) | HR7: =AVERAGE(T7) | HS7: =AVERAGE(P7) | HT7: =AVERAGE(W7,R7,F7) | HV7: =AVERAGE(X7) | HY7: =AVERAGE(Y7)
B8: 2 | C8: 052-25-126006 | D8: Muhammad Zaid | E8: 75 | F8: 73.33 | G8: 81.48 | H8: 9.88 | I8: 59.872222 | L8: 90.33 | N8: 77.78 | O8: 77.78 | P8: 51.11 | Q8: 79.39 | R8: 82.88 | S8: 92.5 | T8: 83.83 | V8: 85.36 | W8: 74.93 | X8: 100 | Y8: 70.56 | Z8: 78 | AA8: 76.25 | AB8: 74.5 | AC8: 82.22 | AD8: 23.809524 | AE8: 15 | AF8: 51.527778 | AG8: 45 | AH8: 74.05 | AI8: 73.43 | AJ8: 62 | AK8: 79.74 | AL8: 100 | AM8: 16 | AN8: 2.38 | AO8: 14.72 | AP8: 26 | AQ8: 50.67 | AR8: 58.81 | AS8: 68 | AT8: 64 | AU8: 42.5 | AV8: 50.83 | AW8: 58.33 | AX8: 50 | HP8: =AVERAGE(G8,L8,N8) | HQ8: =AVERAGE(E8,H8,O8,Q8,S8,V8,Z8) | HR8: =AVERAGE(T8) | HS8: =AVERAGE(P8) | HT8: =AVERAGE(W8,R8,F8) | HV8: =AVERAGE(X8) | HY8: =AVERAGE(Y8)
B9: 3 | C9: 052-25-126016 | D9: Faham Khan | E9: 70 | F9: 62.22 | G9: 82.96 | H9: 79.85 | I9: 52.25 | L9: 81.1 | N9: 64 | O9: 70.56 | P9: 50.56 | Q9: 61.52 | R9: 59.55 | S9: 82.5 | T9: 82.58 | V9: 84.64 | W9: 83.54 | X9: 100 | Y9: 69.44 | Z9: 72 | AA9: 60 | AB9: 64.5 | AC9: 64.44 | AD9: 19.047619 | AE9: 56.25 | AF9: 68.75 | AG9: 45 | AH9: 33.1 | AI9: 37.14 | AJ9: 25.33 | AK9: 77.24 | AN9: 16.67 | AO9: 0 | AP9: 72 | AQ9: 51.56 | AR9: 57.38 | AS9: 56 | AT9: 56 | AU9: 2.78 | AV9: 2.08 | AW9: 8.33 | AX9: 25 | HP9: =AVERAGE(G9,L9,N9) | HQ9: =AVERAGE(E9,H9,O9,Q9,S9,V9,Z9) | HR9: =AVERAGE(T9) | HS9: =AVERAGE(P9) | HT9: =AVERAGE(W9,R9,F9) | HV9: =AVERAGE(X9) | HY9: =AVERAGE(Y9)
B10: 4 | C10: 052-25-126020 | D10: Muhammad Sudais | E10: 75 | F10: 78.89 | G10: 89.26 | H10: 83.64 | I10: 57.183333 | L10: 86.58 | N10: 50 | O10: 61.11 | P10: 57.78 | Q10: 66.67 | R10: 75.91 | S10: 92.5 | T10: 86.75 | V10: 73.21 | W10: 73.89 | X10: 100 | Y10: 58.89 | Z10: 74 | AA10: 86.25 | AB10: 90 | AC10: 84.44 | AD10: 93.333333 | AE10: 92.5 | AF10: 80.079365 | AG10: 92.307692 | AH10: 83.81 | AI10: 81.14 | AJ10: 72.67 | AK10: 65.99 | AL10: 85 | AM10: 16 | AN10: 56.19 | AO10: 35.56 | AP10: 61.67 | AQ10: 64.59 | AR10: 58.81 | AS10: 52 | AT10: 72 | AU10: 40 | AV10: 47.5 | AW10: 41.67 | AX10: 75 | HP10: =AVERAGE(G10,L10,N10) | HQ10: =AVERAGE(E10,H10,O10,Q10,S10,V10,Z10) | HR10: =AVERAGE(T10) | HS10: =AVERAGE(P10) | HT10: =AVERAGE(W10,R10,F10) | HV10: =AVERAGE(X10) | HY10: =AVERAGE(Y10)
B11: 5 | C11: 052-25-126028 | D11: Hina Qamar | E11: 81.67 | F11: 87.78 | G11: 84.81 | H11: 86.06 | I11: 88.08 | L11: 90.9 | N11: 96 | O11: 90.56 | P11: 83.89 | Q11: 86.97 | R11: 91.21 | S11: 95 | T11: 83.58 | V11: 86.43 | W11: 82.08 | X11: 100 | Y11: 71.11 | Z11: 78 | AA11: 70.42 | AB11: 68.5 | AC11: 73.33 | AD11: 29.047619 | AE11: 42.5 | AF11: 38.90873 | AG11: 56.538462 | AH11: 90.48 | AI11: 89.43 | AJ11: 90.67 | AK11: 87.19 | AL11: 100 | AM11: 16 | AN11: 74.29 | AO11: 82.64 | AP11: 89.33 | AQ11: 84.89 | AR11: 89.76 | AS11: 97.33 | AT11: 92 | AU11: 80.83 | AV11: 83.33 | AW11: 75 | AX11: 25 | HP11: =AVERAGE(G11,L11,N11) | HQ11: =AVERAGE(E11,H11,O11,Q11,S11,V11,Z11) | HR11: =AVERAGE(T11) | HS11: =AVERAGE(P11) | HT11: =AVERAGE(W11,R11,F11) | HV11: =AVERAGE(X11) | HY11: =AVERAGE(Y11)
B12: 6 | C12: 052-25-126035 | D12: Muhammad Talha | E12: 53.33 | F12: 52.22 | G12: 63.7 | H12: 68.71 | I12: 12.666667 | L12: 20.42 | N12: 18 | O12: 26.67 | P12: 15 | Q12: 21.21 | R12: 9.09 | S12: 85 | T12: 78 | V12: 65 | W12: 70.63 | X12: 100 | Y12: 57.78 | Z12: 74 | AA12: 46.25 | AB12: 43.5 | AC12: 44.3 | AD12: 34.285714 | AE12: 62.5 | AF12: 54.22619 | AG12: 91.153846 | AH12: 5.71 | AI12: 11.43 | AJ12: 3.33 | AK12: 60.63 | AN12: 0 | AO12: 6.67 | AP12: 0 | AQ12: 8.89 | AR12: 7.14 | AS12: 3.33 | AT12: 0 | AU12: 5.56 | AV12: 22.92 | AW12: 8.33 | AX12: 100 | HP12: =AVERAGE(G12,L12,N12) | HQ12: =AVERAGE(E12,H12,O12,Q12,S12,V12,Z12) | HR12: =AVERAGE(T12) | HS12: =AVERAGE(P12) | HT12: =AVERAGE(W12,R12,F12) | HV12: =AVERAGE(X12) | HY12: =AVERAGE(Y12)
B13: 7 | C13: 052-25-126036 | D13: Yahya Sohail | E13: 78.33 | F13: 72.22 | G13: 84.44 | H13: 81.67 | I13: 65.8 | L13: 89.66 | N13: 74 | O13: 60 | P13: 60.56 | Q13: 77.27 | R13: 84.55 | S13: 97.5 | T13: 80 | V13: 84.29 | W13: 72.12 | X13: 100 | Y13: 58.33 | Z13: 72 | AA13: 69.17 | AB13: 64.5 | AC13: 66.67 | AD13: 37.619048 | AE13: 62.5 | AF13: 66.071429 | AG13: 68.076923 | AH13: 61.43 | AI13: 59.14 | AJ13: 59.33 | AK13: 64.06 | AL13: 100 | AM13: 16 | AN13: 36.67 | AO13: 36.11 | AP13: 57.33 | AQ13: 53.04 | AR13: 62.38 | AS13: 50 | AT13: 68 | AU13: 36.53 | AV13: 30.83 | AW13: 25 | AX13: 87.5 | HP13: =AVERAGE(G13,L13,N13) | HQ13: =AVERAGE(E13,H13,O13,Q13,S13,V13,Z13) | HR13: =AVERAGE(T13) | HS13: =AVERAGE(P13) | HT13: =AVERAGE(W13,R13,F13) | HV13: =AVERAGE(X13) | HY13: =AVERAGE(Y13)
B14: 8 | C14: 052-25-126044 | D14: Muhammad Faraz Yousaf | E14: 80 | F14: 66.67 | G14: 52.96 | H14: 80 | I14: 52.683333 | L14: 51.11 | N14: 72 | O14: 60 | P14: 58.89 | Q14: 62.73 | R14: 73.18 | S14: 85 | T14: 79.5 | V14: 83.93 | W14: 77.99 | X14: 90 | Y14: 70.56 | Z14: 74 | AA14: 92.5 | AB14: 95.5 | AC14: 95.56 | AD14: 63.333333 | AE14: 68.75 | AF14: 65.138889 | AG14: 64.230769 | AH14: 44.05 | AI14: 31.14 | AJ14: 36 | AK14: 62.14 | AL14: 100 | AM14: 16 | AN14: 0 | AO14: 0 | AP14: 26 | AQ14: 8.89 | AR14: 7.14 | AS14: 0 | AT14: 0 | AU14: 15 | AV14: 10 | AW14: 0 | AX14: 0 | HP14: =AVERAGE(G14,L14,N14) | HQ14: =AVERAGE(E14,H14,O14,Q14,S14,V14,Z14) | HR14: =AVERAGE(T14) | HS14: =AVERAGE(P14) | HT14: =AVERAGE(W14,R14,F14) | HV14: =AVERAGE(X14) | HY14: =AVERAGE(Y14)
B15: 9 | C15: 052-25-126045 | D15: Yasir Abbas | E15: 73.33 | F15: 91.11 | G15: 87.78 | H15: 84.55 | I15: 76.9 | L15: 88.32 | N15: 74 | O15: 90.56 | P15: 73.33 | Q15: 84.85 | R15: 78.18 | S15: 97.5 | T15: 97.25 | V15: 70.71 | W15: 73.78 | X15: 100 | Y15: 60.56 | Z15: 70 | AA15: 76.67 | AB15: 71.5 | AC15: 71.11 | AD15: 90.47619 | AE15: 95 | AF15: 92.5 | AG15: 84.615385 | AH15: 60 | AI15: 60 | AJ15: 63.33 | AK15: 78.85 | AL15: 100 | AM15: 16 | AN15: 57.62 | AO15: 55.97 | AP15: 68.67 | AQ15: 52.89 | AR15: 65.95 | AS15: 53.33 | AT15: 60 | AU15: 67.5 | AV15: 67.5 | AW15: 33.33 | AX15: 75 | HP15: =AVERAGE(G15,L15,N15) | HQ15: =AVERAGE(E15,H15,O15,Q15,S15,V15,Z15) | HR15: =AVERAGE(T15) | HS15: =AVERAGE(P15) | HT15: =AVERAGE(W15,R15,F15) | HV15: =AVERAGE(X15) | HY15: =AVERAGE(Y15)
B16: 10 | C16: 052-25-126046 | D16: Numan Khan | E16: 70 | F16: 61.11 | G16: 78.89 | H16: 71.44 | I16: 26.966667 | L16: 85.74 | N16: 72 | O16: 51.67 | P16: 51.11 | Q16: 76.97 | R16: 80 | S16: 92.5 | T16: 82.17 | V16: 78.57 | W16: 65 | X16: 100 | Y16: 60.56 | Z16: 82 | AA16: 71.25 | AB16: 67.5 | AC16: 71.11 | AD16: 75.238095 | AE16: 71.25 | AF16: 65.515873 | AG16: 91.153846 | AH16: 49.52 | AI16: 51.14 | AJ16: 48.67 | AK16: 57.03 | AL16: 82.5 | AM16: 16 | AN16: 50 | AO16: 40 | AP16: 58.17 | AQ16: 51.26 | AR16: 65.95 | AS16: 52.67 | AT16: 56 | AU16: 31.39 | AV16: 40.83 | AW16: 66.67 | AX16: 37.5 | HP16: =AVERAGE(G16,L16,N16) | HQ16: =AVERAGE(E16,H16,O16,Q16,S16,V16,Z16) | HR16: =AVERAGE(T16) | HS16: =AVERAGE(P16) | HT16: =AVERAGE(W16,R16,F16) | HV16: =AVERAGE(X16) | HY16: =AVERAGE(Y16)
B17: 11 | C17: 052-25-126058 | D17: Zainab Hanif | E17: 86.67 | F17: 85.56 | G17: 87.41 | H17: 92.27 | I17: 80.15 | L17: 91.72 | N17: 94 | O17: 92.22 | P17: 91.11 | Q17: 90.61 | R17: 97.58 | S17: 100 | T17: 84.25 | V17: 79.29 | W17: 86.6 | X17: 90 | Y17: 73.33 | Z17: 80 | AA17: 83.33 | AB17: 82 | AC17: 88.89 | AD17: 0 | AE17: 0 | AF17: 0 | AG17: 0 | AH17: 95.71 | AI17: 89.43 | AJ17: 100 | AK17: 91.82 | AL17: 100 | AM17: 16 | AN17: 47.14 | AO17: 35.69 | AP17: 65.33 | AQ17: 84.89 | AR17: 89.76 | AS17: 97.33 | AT17: 92 | AU17: 71.39 | AV17: 80 | AW17: 66.67 | AX17: 87.5 | HP17: =AVERAGE(G17,L17,N17) | HQ17: =AVERAGE(E17,H17,O17,Q17,S17,V17,Z17) | HR17: =AVERAGE(T17) | HS17: =AVERAGE(P17) | HT17: =AVERAGE(W17,R17,F17) | HV17: =AVERAGE(X17) | HY17: =AVERAGE(Y17)
B18: 12 | C18: 052-25-126072 | D18: Aryan Khalid | E18: 75 | F18: 75.56 | G18: 91.48 | H18: 93.64 | I18: 85.566667 | L18: 81.64 | N18: 90 | O18: 91.67 | P18: 80 | Q18: 87.88 | R18: 80.91 | S18: 90 | T18: 89.42 | V18: 81.79 | W18: 81.77 | X18: 90 | Y18: 70 | Z18: 66 | AA18: 271.25 | AB18: 67.5 | AC18: 71.11 | AD18: 83.809524 | AE18: 87.5 | AF18: 78.710317 | AG18: 84.615385 | AH18: 48.41 | AI18: 50.86 | AJ18: 54 | AK18: 0 | AL18: 100 | AM18: 16 | AN18: 47.14 | AO18: 35.69 | AP18: 65.33 | AQ18: 42.22 | AR18: 37.14 | AS18: 28 | AT18: 32 | AU18: 28.89 | AV18: 26.67 | AW18: 67.67 | AX18: 75 | HP18: =AVERAGE(G18,L18,N18) | HQ18: =AVERAGE(E18,H18,O18,Q18,S18,V18,Z18) | HR18: =AVERAGE(T18) | HS18: =AVERAGE(P18) | HT18: =AVERAGE(W18,R18,F18) | HV18: =AVERAGE(X18) | HY18: =AVERAGE(Y18)
B19: 13 | C19: 052-25-126075 | D19: Wajahat Nawaz Khan | E19: 35 | F19: 22 | G19: 34.81 | H19: 45.45 | I19: 7.1666667 | Q19: 28.18 | R19: 2.73 | S19: 25 | V19: 10.71 | W19: 8.54 | Y19: 0 | Z19: 0 | AA19: 67.92 | AB19: 65.5 | AC19: 75.56 | AD19: 96.666667 | AE19: 85 | AF19: 80.674603 | AG19: 68.076923 | AH19: 52.62 | AI19: 60.57 | AJ19: 37.33 | AK19: 0 | AN19: 0 | AO19: 0 | AP19: 0 | AU19: 0 | AV19: 0 | AW19: 0 | AX19: 0 | HP19: =AVERAGE(G19,L19,N19) | HQ19: =AVERAGE(E19,H19,O19,Q19,S19,V19,Z19) | HT19: =AVERAGE(W19,R19,F19) | HY19: =AVERAGE(Y19)
B20: 14 | C20: 052-25-126082 | D20: Dawood Alam Shami | E20: 83.33 | F20: 75.56 | G20: 92.96 | H20: 95.08 | I20: 58.733333 | L20: 56.92 | N20: 80 | O20: 76.67 | P20: 69.44 | Q20: 61.82 | R20: 59.39 | S20: 92.5 | T20: 91.42 | V20: 87.86 | W20: 71.15 | X20: 90 | Y20: 65 | Z20: 80 | AA20: 83.75 | AB20: 78.5 | AC20: 80 | AD20: 63.333333 | AE20: 32.5 | AF20: 43.214286 | AG20: 61.730769 | AH20: 58.57 | AI20: 53.71 | AJ20: 49.33 | AK20: 67.92 | AN20: 57.14 | AO20: 46.81 | AP20: 75.67 | AQ20: 40.74 | AR20: 7.14 | AS20: 32 | AT20: 28 | AU20: 59.17 | AV20: 53.33 | AW20: 25 | AX20: 25 | HP20: =AVERAGE(G20,L20,N20) | HQ20: =AVERAGE(E20,H20,O20,Q20,S20,V20,Z20) | HR20: =AVERAGE(T20) | HS20: =AVERAGE(P20) | HT20: =AVERAGE(W20,R20,F20) | HV20: =AVERAGE(X20) | HY20: =AVERAGE(Y20)
B21: 15 | C21: 052-25-126088 | D21: Abid Khan | E21: 85 | F21: 72.22 | G21: 90.74 | H21: 85 | I21: 69.033333 | L21: 88.6 | N21: 70 | O21: 67.78 | P21: 66.67 | Q21: 82.42 | R21: 78.64 | S21: 97.5 | T21: 87.58 | V21: 83.93 | W21: 74.93 | X21: 100 | Y21: 71.11 | Z21: 88 | AA21: 56.25 | AB21: 59.5 | AC21: 66.67 | AD21: 56.666667 | AE21: 43.75 | AF21: 70.138889 | AG21: 27.5 | AH21: 71.9 | AI21: 70.29 | AJ21: 67.33 | AK21: 89.11 | AL21: 95.83 | AM21: 14 | AN21: 67.14 | AO21: 46.53 | AP21: 60.33 | AQ21: 69.48 | AR21: 65.95 | AS21: 63.33 | AT21: 72 | AU21: 0 | AV21: 0 | AW21: 0 | AX21: 0 | HP21: =AVERAGE(G21,L21,N21) | HQ21: =AVERAGE(E21,H21,O21,Q21,S21,V21,Z21) | HR21: =AVERAGE(T21) | HS21: =AVERAGE(P21) | HT21: =AVERAGE(W21,R21,F21) | HV21: =AVERAGE(X21) | HY21: =AVERAGE(Y21)
B22: 16 | C22: 052-25-126097 | D22: Fahad Nasir Abbasi | E22: 76.67 | F22: 77.78 | G22: 93.33 | H22: 92.73 | I22: 60.983333 | L22: 85.28 | N22: 60 | O22: 67.78 | P22: 50 | Q22: 62.42 | R22: 66.52 | S22: 97.5 | T22: 86.5 | V22: 77.86 | W22: 81.88 | X22: 100 | Y22: 61.67 | Z22: 64 | AA22: 67.08 | AB22: 67.5 | AC22: 66.67 | AD22: 0 | AE22: 0 | AF22: 0 | AG22: 0 | AH22: 60.71 | AI22: 58.57 | AJ22: 46 | AK22: 50.57 | AL22: 68.33 | AM22: 18 | AN22: 66.19 | AO22: 33.06 | AP22: 59 | AQ22: 50.67 | AR22: 58.81 | AS22: 62 | AT22: 60 | AU22: 36.94 | AV22: 39.17 | AW22: 29.17 | AX22: 75 | HP22: =AVERAGE(G22,L22,N22) | HQ22: =AVERAGE(E22,H22,O22,Q22,S22,V22,Z22) | HR22: =AVERAGE(T22) | HS22: =AVERAGE(P22) | HT22: =AVERAGE(W22,R22,F22) | HV22: =AVERAGE(X22) | HY22: =AVERAGE(Y22)
B23: 17 | C23: 052-25-126099 | D23: Abdul Saboor Malik | E23: 85 | F23: 71.11 | G23: 89.26 | H23: 85.91 | I23: 76.6 | L23: 79.05 | N23: 90 | O23: 77.22 | P23: 60.56 | Q23: 84.24 | R23: 81.52 | S23: 92.5 | T23: 89.33 | V23: 82.14 | W23: 81.08 | X23: 100 | Y23: 71.67 | Z23: 82 | AA23: 56.67 | AB23: 63.5 | AC23: 68.89 | AD23: 60.952381 | AE23: 47.5 | AF23: 56.448413 | AG23: 91.153846 | AH23: 66.67 | AI23: 69.14 | AJ23: 68.67 | AK23: 48.13 | AN23: 56.19 | AO23: 44.31 | AP23: 55.17 | AQ23: 50.81 | AR23: 52.14 | AS23: 50.67 | AT23: 52 | AU23: 46.67 | AV23: 26.67 | AW23: 58.33 | AX23: 25 | HP23: =AVERAGE(G23,L23,N23) | HQ23: =AVERAGE(E23,H23,O23,Q23,S23,V23,Z23) | HR23: =AVERAGE(T23) | HS23: =AVERAGE(P23) | HT23: =AVERAGE(W23,R23,F23) | HV23: =AVERAGE(X23) | HY23: =AVERAGE(Y23)
B24: 18 | C24: 052-25-126105 | D24: Haider Saleem | E24: 70 | F24: 57.78 | G24: 44.81 | H24: 74.24 | I24: 55.883333 | L24: 78.48 | N24: 56 | O24: 57.78 | P24: 34.44 | Q24: 60.3 | R24: 78.48 | S24: 80 | T24: 77.67 | V24: 73.21 | W24: 80.14 | X24: 90 | Y24: 53.33 | Z24: 64 | AA24: 63.75 | AB24: 66 | AC24: 66.67 | AD24: 0 | AE24: 0 | AF24: 0 | AG24: 0 | AH24: 54.05 | AI24: 54 | AJ24: 32.67 | AK24: 48.13 | AL24: 65 | AM24: 18 | AN24: 52.38 | AO24: 31.25 | AP24: 34.67 | AQ24: 50.22 | AR24: 54.52 | AS24: 53.33 | AT24: 52 | AU24: 26.39 | AV24: 29.17 | AW24: 8.33 | AX24: 75 | HP24: =AVERAGE(G24,L24,N24) | HQ24: =AVERAGE(E24,H24,O24,Q24,S24,V24,Z24) | HR24: =AVERAGE(T24) | HS24: =AVERAGE(P24) | HT24: =AVERAGE(W24,R24,F24) | HV24: =AVERAGE(X24) | HY24: =AVERAGE(Y24)
B25: 19 | C25: 052-25-126109 | D25: Shahab Ali | E25: 75 | F25: 71.11 | G25: 92.59 | H25: 88.26 | I25: 62.533333 | L25: 88.62 | N25: 78 | O25: 77.22 | P25: 62.78 | Q25: 73.94 | R25: 86.82 | S25: 87.5 | T25: 84.5 | V25: 77.86 | W25: 75.56 | X25: 100 | Y25: 65 | Z25: 76 | AA25: 88.33 | AB25: 82.5 | AC25: 93.33 | AD25: 49.047619 | AE25: 73.75 | AF25: 86.626984 | AG25: 92.307692 | AH25: 85.95 | AI25: 82.86 | AJ25: 81.33 | AK25: 70.26 | AL25: 100 | AM25: 18 | AN25: 52.38 | AO25: 41.39 | AP25: 62.83 | AQ25: 72.59 | AR25: 65.95 | AS25: 52 | AT25: 64 | AU25: 25.83 | AV25: 14.17 | AW25: 33.33 | AX25: 50 | HP25: =AVERAGE(G25,L25,N25) | HQ25: =AVERAGE(E25,H25,O25,Q25,S25,V25,Z25) | HR25: =AVERAGE(T25) | HS25: =AVERAGE(P25) | HT25: =AVERAGE(W25,R25,F25) | HV25: =AVERAGE(X25) | HY25: =AVERAGE(Y25)
B26: 20 | C26: 052-25-126111 | D26: Syed Murtaza Asad | E26: 71.67 | F26: 60 | G26: 81.48 | H26: 83.26 | I26: 21.633333 | L26: 26.78 | N26: 50 | O26: 13.33 | P26: 21.67 | Q26: 63.03 | R26: 64.24 | S26: 92.5 | T26: 76.92 | V26: 76.79 | W26: 78.68 | X26: 90 | Y26: 61.67 | Z26: 86 | AA26: 67.92 | AB26: 65.5 | AC26: 71.11 | AD26: 28.095238 | AE26: 32.5 | AF26: 48.75 | AG26: 45 | AH26: 0 | AI26: 0 | AJ26: 0 | AK26: 0 | AN26: 0 | AO26: 0 | AP26: 0 | AU26: 0 | AV26: 0 | AW26: 0 | AX26: 0 | HP26: =AVERAGE(G26,L26,N26) | HQ26: =AVERAGE(E26,H26,O26,Q26,S26,V26,Z26) | HR26: =AVERAGE(T26) | HS26: =AVERAGE(P26) | HT26: =AVERAGE(W26,R26,F26) | HV26: =AVERAGE(X26) | HY26: =AVERAGE(Y26)
B27: 21 | C27: 052-25-126145 | D27: Raja Haris Waqar | E27: 80 | F27: 66.67 | G27: 71.11 | H27: 81.21 | I27: 19.833333 | L27: 66 | N27: 46 | O27: 41.67 | P27: 15.56 | Q27: 39.09 | R27: 37.12 | S27: 80 | T27: 84.17 | V27: 82.86 | W27: 77.22 | X27: 90 | Y27: 47.78 | Z27: 76 | AA27: 65 | AB27: 47.5 | AC27: 71.11 | AD27: 9.5238095 | AE27: 5 | AF27: 3.3333333 | AG27: 0 | AH27: 53.33 | AI27: 54 | AJ27: 48.67 | AK27: 59.95 | AN27: 54.29 | AO27: 24.17 | AP27: 45.33 | AQ27: 51.56 | AR27: 57.14 | AS27: 52.67 | AT27: 56 | AU27: 40.83 | AV27: 32.5 | AW27: 8.33 | AX27: 62.5 | HP27: =AVERAGE(G27,L27,N27) | HQ27: =AVERAGE(E27,H27,O27,Q27,S27,V27,Z27) | HR27: =AVERAGE(T27) | HS27: =AVERAGE(P27) | HT27: =AVERAGE(W27,R27,F27) | HV27: =AVERAGE(X27) | HY27: =AVERAGE(Y27)
B28: 22 | C28: 052-25-126155 | D28: Zulfiqar Ali | E28: 75 | F28: 83.33 | G28: 95.19 | H28: 95.83 | I28: 59.92 | L28: 61.59 | N28: 72 | O28: 63.33 | P28: 78.89 | Q28: 76.06 | R28: 68.64 | S28: 95 | T28: 87.08 | V28: 82.86 | W28: 78.37 | X28: 100 | Y28: 60.56 | Z28: 64 | AA28: 49.58 | AB28: 48.5 | AC28: 57.78 | AD28: 62.380952 | AE28: 53.75 | AF28: 62.242063 | AG28: 68.076923 | AH28: 57.86 | AI28: 61.43 | AJ28: 42.67 | AK28: 60.99 | AL28: 100 | AM28: 16 | AN28: 44.76 | AO28: 45 | AP28: 56.17 | AQ28: 39.56 | AR28: 28.81 | AS28: 20 | AT28: 28 | AU28: 36.94 | AV28: 43.33 | AW28: 8.33 | AX28: 75 | HP28: =AVERAGE(G28,L28,N28) | HQ28: =AVERAGE(E28,H28,O28,Q28,S28,V28,Z28) | HR28: =AVERAGE(T28) | HS28: =AVERAGE(P28) | HT28: =AVERAGE(W28,R28,F28) | HV28: =AVERAGE(X28) | HY28: =AVERAGE(Y28)
B29: 23 | C29: 052-25-126164 | D29: Abdal Khan | E29: 60 | F29: 63.33 | G29: 58.89 | H29: 78.71 | I29: 51.17 | L29: 31.41 | N29: 34 | O29: 40 | P29: 25 | Q29: 54.85 | R29: 51.52 | S29: 92.5 | T29: 81 | V29: 65.71 | W29: 73.33 | X29: 90 | Y29: 61.11 | Z29: 76 | AA29: 72.08 | AB29: 70 | AC29: 60 | AD29: 0 | AE29: 0 | AF29: 0 | AG29: 0 | AH29: 0 | AI29: 0 | AJ29: 0 | AK29: 0 | AL29: 85 | AM29: 16 | AN29: 0 | AO29: 0 | AP29: 0 | AU29: 56.11 | AV29: 42.5 | AW29: 75 | AX29: 75 | HP29: =AVERAGE(G29,L29,N29) | HQ29: =AVERAGE(E29,H29,O29,Q29,S29,V29,Z29) | HR29: =AVERAGE(T29) | HS29: =AVERAGE(P29) | HT29: =AVERAGE(W29,R29,F29) | HV29: =AVERAGE(X29) | HY29: =AVERAGE(Y29)
B30: 24 | C30: 052-25-126166 | D30: Mohsin Muzafar | E30: 58.33 | F30: 62.22 | G30: 60.37 | H30: 77.5 | I30: 30.58 | L30: 28.93 | N30: 66 | O30: 65.56 | P30: 52 | Q30: 81.21 | R30: 77.42 | S30: 85 | T30: 76.08 | V30: 69.29 | W30: 73.47 | X30: 90 | Y30: 62.22 | Z30: 76 | AA30: 66.4 | AB30: 66.5 | AC30: 66.67 | AD30: 0 | AE30: 0 | AF30: 0 | AG30: 0 | AH30: 60.71 | AI30: 60 | AJ30: 39.33 | AK30: 58.39 | AL30: 97.5 | AM30: 16 | AN30: 23.33 | AO30: 28.19 | AP30: 62.83 | AQ30: 54.67 | AR30: 57.38 | AS30: 52.67 | AT30: 68 | AU30: 23.33 | AV30: 26.25 | AW30: 8.33 | AX30: 62.5 | HP30: =AVERAGE(G30,L30,N30) | HQ30: =AVERAGE(E30,H30,O30,Q30,S30,V30,Z30) | HR30: =AVERAGE(T30) | HS30: =AVERAGE(P30) | HT30: =AVERAGE(W30,R30,F30) | HV30: =AVERAGE(X30) | HY30: =AVERAGE(Y30)
B31: Class Average | E31: =AVERAGE(E7:E25) | F31: =AVERAGE(F7:F25) | G31: =AVERAGE(G7:G25) | H31: =AVERAGE(H7:H25) | I31: =AVERAGE(I7:I25) | L31: =AVERAGE(L7:L25) | N31: =AVERAGE(N7:N25) | O31: =AVERAGE(O7:O25) | P31: =AVERAGE(P7:P25) | Q31: =AVERAGE(Q7:Q25) | R31: =AVERAGE(R7:R25) | S31: =AVERAGE(S7:S25) | T31: =AVERAGE(T7:T25) | V31: =AVERAGE(V7:V25) | W31: =AVERAGE(W7:W25) | X31: =AVERAGE(X7:X25) | Y31: =AVERAGE(Y7:Y25) | Z31: =AVERAGE(Z7:Z25) | AA31: =AVERAGE(AA7:AA25) | AB31: =AVERAGE(AB7:AB25) | AC31: =AVERAGE(AC7:AC25) | ... EO31: =AVERAGE(EO7:EO25) | EQ31: =AVERAGE(EQ7:EQ25) | ER31: =AVERAGE(ER7:ER25) | ES31: =AVERAGE(ES7:ES25) | ET31: =AVERAGE(ET7:ET25) | EU31: =AVERAGE(EU7:EU25) | EV31: =AVERAGE(EV7:EV25) | EW31: =AVERAGE(EW7:EW25) | EY31: =AVERAGE(EY7:EY25) | EZ31: =AVERAGE(EZ7:EZ25) | FA31: =AVERAGE(FA7:FA25) | FB31: =AVERAGE(FB7:FB25) | FC31: =AVERAGE(FC7:FC25) | FD31: =AVERAGE(FD7:FD25) | FE31: =AVERAGE(FE7:FE25) | FF31: =AVERAGE(FF7:FF25) | ... HN31: =AVERAGE(HN7:HN25) | HP31: =AVERAGE(HP7:HP30) | HQ31: =AVERAGE(HQ7:HQ30) | HR31: =AVERAGE(HR7:HR30) | HS31: =AVERAGE(HS7:HS30) | HT31: =AVERAGE(HT7:HT30) | HV31: =AVERAGE(HV7:HV30) | HY31: =AVERAGE(HY7:HY30)

Sheet AI-FA-24
A1: Batch Fall 2025 | CW1: Assessment of GA's | HU1: Attainment of GAs | HV1: Attainment of Graduate Attribute
B2: Sr. No. | D2: Student Name | E2: Semester 3 | AE2: Semester 2 | BE2: Semester 3 | CB2: Semester 4 | CW2: Semester 5 | EF2: Semester 6 | FI2: Semester 7 | GO2: Semester - 8
E3: Computer Organization & Assembly Language | J3: Computer Networks | O3: DATA STRUCTURES | U3: ARTIFICIAL INTELLIGENCE | Z3: PROBABILITY & STATISTICS | AC3: Understanding of the Holy Quran-II | AE3: Expository Writing | AH3: Object Oriented Programming | AN3: Discrete Structures | AQ3: Ideology and Constitution of Pakistan | AU3: Digital Logic Design | BB3: Multi Variable Calculus | BE3: Data Structures | BH3: Computer Organization & Assembly Language | BK3: Introduction to Artificial Intelligence | BN3: Computer Network | BU3: Probability & Statistics | CB3: Design Analysis of Algorithms | CH3: Data Structures and Algorithms | CL3: Applied Statistics | CQ3: Software Engineering | CT3: World History | CW3: Artificial Intelligence | DB3: Data Communication & Computer Networks | DG3: Continuous Discreate Optimization | DL3: Data Base Management Systems | DR3: Introduction to Python Lab | DY3: World Literature | EF3: Machine Learning | EK3: Computer Vision | EQ3: Parallel and Distributed Computing | EW3: Academic & Professional Writing | EZ3: Logical And Automated Reasoning | FC3: Data Visualization | FI3: Artificial Intelligence | FN3: Philosophy and Critical Thinking | FP3: Natural Language Processing | FU3: Final Year Project - I | GG3: Logical And Automated Reasoning | GK3: Philosophy and Critical Thinking | GO3: Deep Learning | GT3: Artificial Intelligence for Robotics | GY3: Sociology | HB3: Ethics and Social Responsibility | HE3: Philosophy and Critical Thinking | HI3: Final Year Project - II
